Workbook

Sheet QUESTÃO 1 
A1: Sete Lagoas/MG
A2: Ano | B2: RECEITA BRUTA EM MILHÕES | C2: IPCA (%) | D2: IPCA ACUMULADO (base 2014=100) | E2: RECEITA REAL EM MILHÕES | F2: PIB EM MILHÕES | G2: Receita/PIB | H2: População | I2: Receita per capita | J2: CONTA
A3: 2014 | B3: 585.34 | C3: 0.0641 | D3: 1 | E3: =B3*D3 -> 585.34 | F3: =8054271000/10^6 -> 8054.271 | G3: =E3/F3 -> 0.072674485 | H3: 229887 | I3: =E3/H3*1000000 -> 2546.2075 | J3: Receita Nominal | K3: É o valor da receita original, exatamente como foi coletado nas bases oficiais
A4: 2015 | B4: 627.78914 | C4: 0.1067 | D4: =D3*(C3+1) -> 1.0641 | E4: =B4/D4 -> 589.97194 | F4: =7680951000/10^6 -> 7680.951 | G4: =E4/F4 -> 0.076809752 | H4: 232107 | I4: =E4/H4*1000000 -> 2541.8102 | J4: IPCA (%) | K4: É a inflação anual medida pelo IBGE.
A5: 2016 | B5: 644.09653 | C5: 0.0629 | D5: =D4*(C4+1) -> 1.1776395 | E5: =B5/D5 -> 546.93864 | F5: =7268417000/10^6 -> 7268.417 | G5: =E5/F5 -> 0.07524866 | H5: 234221 | I5: =E5/H5*1000000 -> 2335.1392 | J5: IPCA (base 2024=100) | K5: Aqui eu transformei o índice de inflação em uma base comum (2024 = 100), todos os anos são ajustados como se estivessem no valor de 2024
A6: 2017 | B6: 653.99894 | C6: 0.0295 | D6: =D5*(C5+1) -> 1.251713 | E6: =B6/D6 -> 522.48315 | F6: =8265467000/10^6 -> 8265.467 | G6: =E6/F6 -> 0.06321278 | H6: 236228 | I6: =E6/H6*1000000 -> 2211.7748 | J6: Receita Real | K6: Corrige a receita pela inflação
A7: 2018 | B7: 667.49019 | C7: 0.0375 | D7: =D6*(C6+1) -> 1.2886385 | E7: =B7/D7 -> 517.98093 | F7: =8537314000/10^6 -> 8537.314 | G7: =E7/F7 -> 0.060672588 | H7: 237286 | I7: =E7/H7*1000000 -> 2182.9393 | J7: PIB | K7: Valor do Produto Interno Bruto municipal - IBGE
A8: 2019 | B8: 745.55565 | C8: 0.0431 | D8: =D7*(C7+1) -> 1.3369625 | E8: =B8/D8 -> 557.6489 | F8: =9549062000/10^6 -> 9549.062 | G8: =E8/F8 -> 0.05839829 | H8: 239639 | I8: =E8/H8*1000000 -> 2327.0373 | J8: Receita/PIB | K8: Quanto o governo arrecada em relação à economia
A9: 2020 | B9: 846.21318 | C9: 0.0452 | D9: =D8*(C8+1) -> 1.3945856 | E9: =B9/D9 -> 606.78471 | F9: =9248447000/10^6 -> 9248.447 | G9: =E9/F9 -> 0.065609362 | H9: 241835 | I9: =E9/H9*1000000 -> 2509.0856 | J9: População | K9: Dados populacionais - IBGE
A10: 2021 | B10: 1028.9639 | C10: 0.1006 | D10: =D9*(C9+1) -> 1.4576208 | E10: =B10/D10 -> 705.92015 | F10: =12655800000/10^6 -> 12655.8 | G10: =E10/F10 -> 0.05577839 | H10: 243950 | I10: =E10/H10*1000000 -> 2893.7084 | J10: Receita per capita | K10: Quanto, em média, o município arrecada por habitante
A11: 2022 | B11: 1117.0133 | C11: 0.0579 | D11: =D10*(C10+1) -> 1.6042575 | E11: =B11/D11 -> 696.28058 | F11: =14818544000/10^6 -> 14818.544 | G11: =E11/F11 -> 0.046987111 | H11: 227397 | I11: =E11/H11*1000000 -> 3061.9603
A12: 2023 | B12: 1298.5718 | C12: 0.0462 | D12: =D11*(C11+1) -> 1.697144 | E12: =B12/D12 -> 765.15122 | F12: =14904465000/10^6 -> 14904.465 | G12: =E12/F12 -> 0.051337047 | H12: 232664 | I12: =E12/H12*1000000 -> 3288.6532
A13: 2024 | B13: 1437.2479 | C13: 0.0483 | D13: =D12*(C12+1) -> 1.775552 | E13: =B13/D13 -> 809.4654 | F13: 2024 → PIB: não disponível (IBGE) | H13: 237931 | I13: =E13/H13*1000000 -> 3402.1014
A15: Itaboraí/RJ
A16: ANO | B16: RECEITA BRUTA EM MILHÕES | C16: IPCA (%) | D16: IPCA ACUMULADO (base 2014=100) | E16: RECEITA REAL EM MILHÕES | F16: PIB EM MILHÕES | G16: Receita/PIB | H16: População | I16: Receita per capita
A17: 2014 | B17: 706.84982 | C17: 0.0641 | D17: 1 | E17: =B17*D17 -> 706.84982 | F17: 5053.066 | G17: =B17/F17 -> 0.13988533 | H17: 227168 | I17: =E17/H17*1000000 -> 3111.573
A18: 2015 | B18: 632.74173 | C18: 0.1067 | D18: =D17*(C17+1) -> 1.0641 | E18: =B18/D18 -> 594.62619 | F18: 4312.98 | G18: =B18/F18 -> 0.14670639 | H18: 229007 | I18: =E18/H18*1000000 -> 2596.5416
A19: 2016 | B19: 511.87079 | C19: 0.0629 | D19: =D18*(C18+1) -> 1.1776395 | E19: =B19/D19 -> 434.65832 | F19: 4350.443 | G19: =B19/F19 -> 0.11765946 | H19: 230786 | I19: =E19/H19*1000000 -> 1883.3825
A20: 2017 | B20: 498.36141 | C20: 0.0295 | D20: =D19*(C19+1) -> 1.251713 | E20: =B20/D20 -> 398.14352 | F20: 4186.706 | G20: =B20/F20 -> 0.11903425 | H20: 232394 | I20: =E20/H20*1000000 -> 1713.2263
A21: 2018 | B21: 562.74227 | C21: 0.0375 | D21: =D20*(C20+1) -> 1.2886385 | E21: =B21/D21 -> 436.69521 | F21: 4486.979 | G21: =B21/F21 -> 0.12541674 | H21: 238695 | I21: =E21/H21*1000000 -> 1829.5113
A22: 2019 | B22: 750.42586 | C22: 0.0431 | D22: =D21*(C21+1) -> 1.3369625 | E22: =B22/D22 -> 561.29164 | F22: 4933.377 | G22: =B22/F22 -> 0.152112 | H22: 240592 | I22: =E22/H22*1000000 -> 2332.9605
A23: 2020 | B23: 731.18158 | C23: 0.0452 | D23: =D22*(C22+1) -> 1.3945856 | E23: =B23/D23 -> 524.30027 | F23: 5422.086 | G23: =B23/F23 -> 0.13485245 | H23: 242543 | I23: =E23/H23*1000000 -> 2161.6796
A24: 2021 | B24: 970.71834 | C24: 0.1006 | D24: =D23*(C23+1) -> 1.4576208 | E24: =B24/D24 -> 665.96081 | F24: 5640.678 | G24: =B24/F24 -> 0.17209249 | H24: 244416 | I24: =E24/H24*1000000 -> 2724.7022
A25: 2022 | B25: 1015.047 | C25: 0.0579 | D25: =D24*(C24+1) -> 1.6042575 | E25: =B25/D25 -> 632.72073 | F25: 5640.941 | G25: =B25/F25 -> 0.17994284 | H25: 224267 | I25: =E25/H25*1000000 -> 2821.2832
A26: 2023 | B26: 956.75996 | C26: 0.0462 | D26: =D25*(C25+1) -> 1.697144 | E26: =B26/D26 -> 563.74707 | F26: 6278.393 | G26: =B26/F26 -> 0.15238931 | H26: 232154 | I26: =E26/H26*1000000 -> 2428.3324
A27: 2024 | B27: 1067.8065 | C27: 0.0483 | D27: =D26*(C26+1) -> 1.775552 | E27: =B27/D27 -> 601.39407 | F27: 2024 → PIB: não disponível (IBGE) | H27: 240040 | I27: =E27/H27*1000000 -> 2505.391
A29: O índice foi construído a partir do IPCA acumulado anual do IBGE, convertendo-se para uma base 2024 = 100 por meio de deflação recursiva.

Sheet QUESTÃO 2
A1: MALÁSIA
A2: Ano | B2: PIB | C2: População | D2: PIB Per Capita (US$)
A3: 2014 | B3: US$ 338,07 bilhões | C3: 30696.37 | D3: 11013.03
A4: 2015 | B4: US$ 301,36 bilhões | C4: 31232.798 | D4: 9648.7
A5: 2016 | B5: US$ 301,26 bilhões | C5: 31789.68 | D5: 9476.5
A6: 2017 | B6: US$ 319,11 bilhões | C6: 32355.644 | D6: 9862.5
A7: 2018 | B7: US$ 358,79 bilhões | C7: 32910.967 | D7: 10901.8
A8: 2019 | B8: US$ 365,18 bilhões | C8: 33440.596 | D8: 10920.2
A9: 2020 | B9: US$ 337,46 bilhões | C9: 33889.558 | D9: 9957.5
A10: 2021 | B10: US$ 373,78 bilhões | C10: 34282.399 | D10: 10903.1
A11: 2022 | B11: US$ 407,83 bilhões | C11: 34695.493 | D11: 11754.6
A12: 2023 | B12: US$ 399,95 bilhões | C12: 35126.298 | D12: 11386
A13: 2024 | B13: US$ 422,23 bilhões | C13: 35557.673 | D13: 11874.43
A15: Ano | B15: PIB Per Capita (US$ )
A16: 2014 | B16: ='QUESTÃO 2'!D3 -> 11013.03
A17: 2015 | B17: ='QUESTÃO 2'!D4 -> 9648.7
A18: 2016 | B18: ='QUESTÃO 2'!D5 -> 9476.5
A19: 2017 | B19: ='QUESTÃO 2'!D6 -> 9862.5
A20: 2018 | B20: ='QUESTÃO 2'!D7 -> 10901.8
A21: 2019 | B21: ='QUESTÃO 2'!D8 -> 10920.2
A22: 2020 | B22: ='QUESTÃO 2'!D9 -> 9957.5
A23: 2021 | B23: ='QUESTÃO 2'!D10 -> 10903.1
A24: 2022 | B24: ='QUESTÃO 2'!D11 -> 11754.6
A25: 2023 | B25: ='QUESTÃO 2'!D12 -> 11386
A26: 2024 | B26: ='QUESTÃO 2'!D13 -> 11874.43

Sheet Questão 03
A1: Consulta | B1: Siconfi
B3: ANO | C3: RECEITAS CORRENTES | I3: RECEITAS DE CAPITAL | L3: Total
C4: Tributária | D4: Contribuições | E4: Patrimonial | F4: Serviços | G4: Transferências | H4: Outras | I4: Crédito | J4: Alienação | K4: Capital
A5: Sete lagoas/MG | B5: 2024 | C5: 267.45998 | D5: 29.893944 | E5: 25.365602 | F5: 125.4518 | G5: 861.37348 | H5: 15.498474 | I5: 84.306752 | J5: 3.8742502 | K5: 24.023646 | L5: =SUM(C5:K5) -> 1437.2479
A6: Itaboraí/RJ | B6: 2024 | C6: 219.67181 | D6: 41.964604 | E6: 30.218467 | F6: 5.0411826 | G6: 725.82917 | H6: 26.992601 | I6: 3.8054785 | J6: 0.00389428 | K6: 14.279253 | L6: 1067.8065
B8: SETE LAGOAS | C8: ITABORAÍ
A9: ANO | B9: RECEITA BRUTA EM MILHÕES | C9: RECEITA BRUTA EM MILHÕES
A10: 2014 | B10: 585.34 | C10: 706.84982
A11: 2015 | B11: 627.78914 | C11: 632.74173
A12: 2016 | B12: 644.09653 | C12: 511.87079
A13: 2017 | B13: 653.99894 | C13: 498.36141
A14: 2018 | B14: 667.49019 | C14: 562.74227
A15: 2019 | B15: 745.55565 | C15: 750.42586
A16: 2020 | B16: 846.21318 | C16: 731.18158
A17: 2021 | B17: 1028.9639 | C17: 970.71834
A18: 2022 | B18: 1117.0133 | C18: 1015.047
A19: 2023 | B19: 1298.5718 | C19: 956.75996
A20: 2024 | B20: 1437.2479 | C20: 1067.8065

Sheet QUESTÃO 4
A1: Ano | B1: Receita Sete Lagoas | C1: Despesa Sete Lagoas | D1: Receita Itaboraí | E1: Despesa Itaboraí
A2: 2014 | B2: 5.8533732e+08 | C2: 645331174 | D2: 6.8191556e+08 | E2: 790437191
A3: 2015 | B3: 6.2778914e+08 | C3: 644435731 | D3: 589068033 | E3: 822342538
A4: 2016 | B4: 786492781 | C4: 621166323 | D4: 471523759 | E4: 558555254
A5: 2017 | B5: 591156281 | C5: 601259901 | D5: 456621665 | E5: 497033455
A6: 2018 | B6: 853468621 | C6: 656645938 | D6: 511934070 | E6: 559656288
A7: 2019 | B7: 679687827 | C7: 656290225 | D7: 7.5042586e+08 | E7: 597792199
A8: 2020 | B8: 781570595 | C8: 779638806 | D8: 644912635 | E8: 654784328
A9: 2021 | B9: 1244488929 | C9: 831346913 | D9: 924257901 | E9: 702955391
A10: 2022 | B10: 1.1170133e+09 | C10: 997255336 | D10: 1267904458 | E10: 9.5679356e+08
A11: 2023 | B11: 1200344139 | C11: 1223568670 | D11: 1196398391 | E11: 1084529334
A12: 2024 | B12: 1794285991 | C12: 1414738002 | D12: 1345657064 | E12: 1208679451
A14: Ano | B14: Despesa Sete Lagoas | C14: Despesa Itaboraí
A15: 2014 | B15: =645331174.21/1000000 -> 645.33117 | C15: =790437191.5/1000000 -> 790.43719
A16: 2015 | B16: =644435731.48/1000000 -> 644.43573 | C16: =822342538.02/1000000 -> 822.34254
A17: 2016 | B17: =621166323.43/1000000 -> 621.16632 | C17: =558555254.47/1000000 -> 558.55525
A18: 2017 | B18: =601259901.86/1000000 -> 601.2599 | C18: =497033455.51/1000000 -> 497.03346
A19: 2018 | B19: =656645938.1/1000000 -> 656.64594 | C19: =559656288.3/1000000 -> 559.65629
A20: 2019 | B20: =656290225.41/1000000 -> 656.29023 | C20: =597792199.46/1000000 -> 597.7922
A21: 2020 | B21: =779638806.58/1000000 -> 779.63881 | C21: =654784328.46/1000000 -> 654.78433
A22: 2021 | B22: =831346913.82/1000000 -> 831.34691 | C22: =702955391.93/1000000 -> 702.95539
A23: 2022 | B23: =997255336.12/1000000 -> 997.25534 | C23: =956793564.22/1000000 -> 956.79356
A24: 2023 | B24: =1223568670.24/1000000 -> 1223.5687 | C24: =1084529334/1000000 -> 1084.5293
A25: 2024 | B25: =1414738001.91/1000000 -> 1414.738 | C25: =1208679451.17/1000000 -> 1208.6795

Sheet QUESTÃO 5
A1: SETE LAGOAS - MG
A2: Ano | B2: Gasto Saúde (R$) | C2: Mortalidade Infantil | D2: Correlação | I2: http://tabnet.datasus.gov.br/cgi/deftohtm.exe?sim/cnv/inf10mg.def
A3: 2014 | B3: 1.6243824e+08 | C3: 29 | D3: =CORREL(B3:B7,C3:C7) -> -0.47614442 | E3: correlação negativa moderada
A4: 2015 | B4: 2.0071931e+08 | C4: 35 | I4: https://siconfi.tesouro.gov.br/siconfi/pages/public/consulta_finbra/finbra_list.jsf
A5: 2018 | B5: 2.1646251e+08 | C5: 30
A6: 2019 | B6: 2.2437283e+08 | C6: 37
A7: 2020 | B7: 2.8793369e+08 | C7: 23
A9: ITABORAÍ - RJ
A10: Ano | B10: Gasto Saúde (R$) | C10: Mortalidade Infantil | D10: Correlação
A11: 2014 | B11: 2.0768701e+08 | C11: 37 | D11: =CORREL(B11:B14,C11:C14) -> -0.18435053 | E11: correlação fraca
A12: 2015 | B12: 2.1494161e+08 | C12: 42
A13: 2019 | B13: 1.3763265e+08 | C13: 44
A14: 2020 | B14: 1.825501e+08 | C14: 26

Sheet QUESTÃO 6
A1: SETE LAGOAS - MG | I1: ITABORAÍ - RJ
A2: Ano | B2: Receita Tributária | C2: Receita Total | D2: Carga (proxy) | I2: Ano | J2: Receita Tributária (R$) | K2: Receita Total (R$) | L2: Carga Tributária (%)
A3: 2016 | B3: 117853596 | C3: 786492781 | D3: =B3/C3 -> 0.14984702 | I3: 2015 | J3: 1.8639136e+08 | K3: 5.8906803e+08 | L3: =J3/K3 -> 0.31641737
A4: 2017 | B4: 122488852 | C4: 591156281 | D4: =B4/C4 -> 0.20720215 | I4: 2016 | J4: 81313506 | K4: 4.7152376e+08 | L4: =J4/K4 -> 0.17244838
A5: 2018 | B5: 100930536 | C5: 853468621 | D5: =B5/C5 -> 0.11825922 | I5: 2017 | J5: 74259672 | K5: 4.5662167e+08 | L5: =J5/K5 -> 0.16262845
A6: 2019 | B6: 143327711 | C6: 679687827 | D6: =B6/C6 -> 0.21087285 | I6: 2018 | J6: 1.0248432e+08 | K6: 5.1193407e+08 | L6: =J6/K6 -> 0.20019047
A7: 2020 | B7: 134048601 | C7: 781570595 | D7: =B7/C7 -> 0.17151183 | I7: 2020 | J7: 1.3831382e+08 | K7: 6.4491264e+08 | L7: =J7/K7 -> 0.21446908
A8: 2021 | B8: 177780068 | C8: 1244488929 | D8: =B8/C8 -> 0.14285388 | I8: 2021 | J8: 1.5202371e+08 | K8: 9.242579e+08 | L8: =J8/K8 -> 0.16448191
A9: 2023 | B9: 235469984 | C9: 1200344139 | D9: =B9/C9 -> 0.19616873 | I9: 2022 | J9: 1.7634525e+08 | K9: 1.2679045e+09 | L9: =J9/K9 -> 0.13908402
A10: 2024 | B10: 260495145 | C10: 1794285991 | D10: =B10/C10 -> 0.14518039 | I10: 2023 | J10: 1.8398915e+08 | K10: 1.1963984e+09 | L10: =J10/K10 -> 0.15378586
I11: 2024 | J11: 2.1967181e+08 | K11: 1.3456571e+09 | L11: =J11/K11 -> 0.16324502

Sheet QUESTÃO 7
A1: SETE LAGOAS - MG | G1: ITABORAÍ - RJ
A2: Ano | B2: Receita (R$) | C2: PIB (R$) | D2: b1 | G2: Ano | H2: Receita (R$) | I2: PIB (R$) | J2: b1
A3: 2016 | B3: =786492781.92/1000000 -> 786.49278 | C3: =7268417000/1000000 -> 7268.417 | D3: =SLOPE(B3:B9,C3:C9) -> 0.078726495 | G3: 2015 | H3: =589068033.9/1000000 -> 589.06803 | I3: =4312980000/1000000 -> 4312.98 | J3: =SLOPE(H3:H10,I3:I10) -> 0.36481088
A4: 2017 | B4: =591156281.62/1000000 -> 591.15628 | C4: =8265467000/1000000 -> 8265.467 | G4: 2016 | H4: =471523759.1/1000000 -> 471.52376 | I4: =4350443000/1000000 -> 4350.443
A5: 2018 | B5: =853468621.51/1000000 -> 853.46862 | C5: =8537314000/1000000 -> 8537.314 | G5: 2017 | H5: =456621665.7/1000000 -> 456.62167 | I5: =4186706000/1000000 -> 4186.706
A6: 2019 | B6: =679687827.57/1000000 -> 679.68783 | C6: =9549062000/1000000 -> 9549.062 | G6: 2018 | H6: =511934070.3/1000000 -> 511.93407 | I6: =4486979000/1000000 -> 4486.979
A7: 2020 | B7: =781570595.7/1000000 -> 781.5706 | C7: =9248447000/1000000 -> 9248.447 | G7: 2020 | H7: =644912635.35/1000000 -> 644.91264 | I7: =5422086000/1000000 -> 5422.086
A8: 2021 | B8: =1244488929.85/1000000 -> 1244.4889 | C8: =12655800000/1000000 -> 12655.8 | G8: 2021 | H8: =924257901.03/1000000 -> 924.2579 | I8: =5640678000/1000000 -> 5640.678
A9: 2023 | B9: =1200344139.87/1000000 -> 1200.3441 | C9: =14904465000/1000000 -> 14904.465 | G9: 2022 | H9: =1267904458.69/1000000 -> 1267.9045 | I9: =5640941000/1000000 -> 5640.941
G10: 2023 | H10: =1196398391.4/1000000 -> 1196.3984 | I10: =6278393000/1000000 -> 6278.393

Sheet Questão 08
A2: Consulta | B2: Siconfi | C2: Histórico do IPCA
B4: Sete lagoas/MG
A5: ANO | B5: RECEITA BRUTA EM MILHÕES | C5: IPCA (%) | D5: IPCA ACUMULADO (base 2014=100) | E5: RECEITA REAL EM MILHÕES | F5: RECEITA PER CAPITA (R$/hab)
A6: 2014 | B6: 585.34 | C6: 0.0641 | D6: 1 | E6: =B6*D6 -> 585.34 | F6: =E6/B66*1000000 -> 2546.2075
A7: 2015 | B7: 627.78914 | C7: 0.1067 | D7: =D6*(C6+1) -> 1.0641 | E7: =B7/D7 -> 589.97194 | F7: =E7/B67*1000000 -> 2541.8102
A8: 2016 | B8: 644.09653 | C8: 0.0629 | D8: =D7*(C7+1) -> 1.1776395 | E8: =B8/D8 -> 546.93864 | F8: =E8/B68*1000000 -> 2335.1392
A9: 2017 | B9: 653.99894 | C9: 0.0295 | D9: =D8*(C8+1) -> 1.251713 | E9: =B9/D9 -> 522.48315 | F9: =E9/B69*1000000 -> 2211.7748
A10: 2018 | B10: 667.49019 | C10: 0.0375 | D10: =D9*(C9+1) -> 1.2886385 | E10: =B10/D10 -> 517.98093 | F10: =E10/B70*1000000 -> 2182.9393
A11: 2019 | B11: 745.55565 | C11: 0.0431 | D11: =D10*(C10+1) -> 1.3369625 | E11: =B11/D11 -> 557.6489 | F11: =E11/B71*1000000 -> 2327.0373
A12: 2020 | B12: 846.21318 | C12: 0.0452 | D12: =D11*(C11+1) -> 1.3945856 | E12: =B12/D12 -> 606.78471 | F12: =E12/B72*1000000 -> 2509.0856
A13: 2021 | B13: 1028.9639 | C13: 0.1006 | D13: =D12*(C12+1) -> 1.4576208 | E13: =B13/D13 -> 705.92015 | F13: =E13/B73*1000000 -> 2893.7084
A14: 2022 | B14: 1117.0133 | C14: 0.0579 | D14: =D13*(C13+1) -> 1.6042575 | E14: =B14/D14 -> 696.28058 | F14: =E14/B74*1000000 -> 3061.9603
A15: 2023 | B15: 1298.5718 | C15: 0.0462 | D15: =D14*(C14+1) -> 1.697144 | E15: =B15/D15 -> 765.15122 | F15: =E15/B75*1000000 -> 3288.6532
A16: 2024 | B16: 1437.2479 | C16: 0.0483 | D16: =D15*(C15+1) -> 1.775552 | E16: =B16/D16 -> 809.4654 | F16: =E16/B76*1000000 -> 3402.1014
B18: Minas Gerais/BR
A19: ANO | B19: RECEITA BRUTA EM MILHÕES | C19: IPCA (%) | D19: IPCA ACUMULADO (base 2014=100) | E19: RECEITA REAL EM MILHÕES | F19: RECEITA PER CAPITA (R$/hab)
A20: 2014 | B20: 71225.512 | C20: 0.0641 | D20: 1 | E20: =B20*D20 -> 71225.512 | F20: =E20/D66*1000000 -> 3435.1876
A21: 2015 | B21: 73407.403 | C21: 0.1067 | D21: =D20*(C20+1) -> 1.0641 | E21: =B21/D21 -> 68985.437 | F21: =E21/D67*1000000 -> 3305.6257
A22: 2016 | B22: 78518.824 | C22: 0.0629 | D22: =D21*(C21+1) -> 1.1776395 | E22: =B22/D22 -> 66674.756 | F22: =E22/D68*1000000 -> 3175.3573
A23: 2017 | B23: 80812.068 | C23: 0.0295 | D23: =D22*(C22+1) -> 1.251713 | E23: =B23/D23 -> 64561.18 | F23: =E23/D69*1000000 -> 3056.9412
A24: 2018 | B24: 100746.78 | C24: 0.0375 | D24: =D23*(C23+1) -> 1.2886385 | E24: =B24/D24 -> 78180.793 | F24: =E24/D70*1000000 -> 3715.7003
A25: 2019 | B25: 92186.591 | C25: 0.0431 | D25: =D24*(C24+1) -> 1.3369625 | E25: =B25/D25 -> 68952.265 | F25: =E25/D71*1000000 -> 3257.2604
A26: 2020 | B26: 99781.866 | C26: 0.0452 | D26: =D25*(C25+1) -> 1.3945856 | E26: =B26/D26 -> 71549.476 | F26: =E26/D72*1000000 -> 3360.2874
A27: 2021 | B27: 123251.94 | C27: 0.1006 | D27: =D26*(C26+1) -> 1.4576208 | E27: =B27/D27 -> 84556.929 | F27: =E27/D73*1000000 -> 3949.0581
A28: 2022 | B28: 135337.86 | C28: 0.0579 | D28: =D27*(C27+1) -> 1.6042575 | E28: =B28/D28 -> 84361.681 | F28: =E28/D74*1000000 -> 4107.4463
A29: 2023 | B29: 138168.42 | C29: 0.0462 | D29: =D28*(C28+1) -> 1.697144 | E29: =B29/D29 -> 81412.316 | F29: =E29/D75*1000000 -> 3889.6118
A30: 2024 | B30: 154226.22 | C30: 0.0483 | D30: =D29*(C29+1) -> 1.775552 | E30: =B30/D30 -> 86860.999 | F30: =E30/D76*1000000 -> 4073.6415
B33: Rio de Janeiro/BR
A34: ANO | B34: RECEITA BRUTA EM MILHÕES | C34: IPCA (%) | D34: IPCA ACUMULADO (base 2014=100) | E34: RECEITA REAL EM MILHÕES | F34: RECEITA PER CAPITA (R$/hab)
A35: 2014 | B35: 68191.556 | C35: 0.0641 | D35: 1 | E35: =B35*D35 -> 68191.556 | F35: =E35/E66*1000000 -> 4142.5697
A36: 2015 | B36: 61436.906 | C36: 0.1067 | D36: =D35*(C35+1) -> 1.0641 | E36: =B36/D36 -> 57736.027 | F36: =E36/E67*1000000 -> 3488.5766
A37: 2016 | B37: 50169.036 | C37: 0.0629 | D37: =D36*(C36+1) -> 1.1776395 | E37: =B37/D37 -> 42601.354 | F37: =E37/E68*1000000 -> 2560.7937
A38: 2017 | B38: 48101.449 | C38: 0.0295 | D38: =D37*(C37+1) -> 1.251713 | E38: =B38/D38 -> 38428.497 | F38: =E38/E69*1000000 -> 2298.4986
A39: 2018 | B39: 56274.227 | C39: 0.0375 | D39: =D38*(C38+1) -> 1.2886385 | E39: =B39/D39 -> 43669.521 | F39: =E39/E70*1000000 -> 2544.8498
A40: 2019 | B40: 75042.586 | C40: 0.0431 | D40: =D39*(C39+1) -> 1.3369625 | E40: =B40/D40 -> 56129.164 | F40: =E40/E71*1000000 -> 3251.0483
A41: 2020 | B41: 73118.158 | C41: 0.0452 | D41: =D40*(C40+1) -> 1.3945856 | E41: =B41/D41 -> 52430.027 | F41: =E41/E72*1000000 -> 3019.0865
A42: 2021 | B42: 97071.834 | C42: 0.1006 | D42: =D41*(C41+1) -> 1.4576208 | E42: =B42/D42 -> 66596.081 | F42: =E42/E73*1000000 -> 3813.4771
A43: 2022 | B43: 104274.97 | C43: 0.0579 | D43: =D42*(C42+1) -> 1.6042575 | E43: =B43/D43 -> 64998.901 | F43: =E43/E74*1000000 -> 4048.6346
A44: 2023 | B44: 102646.15 | C44: 0.0462 | D44: =D43*(C43+1) -> 1.697144 | E44: =B44/D44 -> 60481.701 | F44: =E44/E75*1000000 -> 3635.3507
A45: 2024 | B45: 106780.65 | C45: 0.0483 | D45: =D44*(C44+1) -> 1.775552 | E45: =B45/D45 -> 60139.407 | F45: =E45/E76*1000000 -> 3492.4813
...

Sheet QUESTÃO 9
A1: 9) Análise uma falha de mercado e como o gasto público atua (com dados reais). Uma importante falha de mercado presente na área da saúde é a externalidade positiva. Nesse caso, os benefícios gerados pelo consumo de serviços de saúde não se limitam apenas ao indivíduo atendido, mas se estendem a toda a sociedade. Por exemplo, a vacinação e o atendimento básico reduzem a propagação de doenças, beneficiando inclusive pessoas que não utilizaram diretamente o serviço. No entanto, como os agentes privados consideram apenas seus benefícios individuais, o mercado tende a ofertar menos serviços de saúde do que o socialmente desejável, caracterizando uma falha de mercado. Nesse contexto, o gasto público atua corrigindo essa falha por meio da oferta de serviços de saúde e investimentos no sistema público, como o SUS. Evidências empíricas mostram que maiores investimentos em saúde estão associados à redução da mortalidade infantil, indicador amplamente utilizado para medir o bem-estar social. Estudos no Brasil demonstram que municípios com maior gasto em saúde e melhores condições socioeconômicas apresentam menores taxas de mortalidade infantil. Utilizando os dados analisados neste trabalho, observa-se essa relação nos municípios de Sete Lagoas (MG) e Itaboraí (RJ). Em Sete Lagoas, o aumento do gasto com saúde de aproximadamente R$ 162 milhões (2014) para R$ 287 milhões (2020) foi acompanhado pela queda da mortalidade infantil de 29 para 23 óbitos. Em Itaboraí, apesar de oscilações, o aumento do gasto em 2020 também coincidiu com uma redução significativa da mortalidade infantil de 44 para 26 óbitos. Esses resultados indicam uma correlação negativa entre gasto público em saúde e mortalidade infantil, evidenciando que a atuação do Estado contribui para corrigir a falha de mercado, promovendo maior eficiência social e melhoria das condições de vida da população. Portanto, a intervenção do Estado é essencial para garantir a provisão adequada de bens públicos e corrigir ineficiências do mercado, especialmente em setores essenciais como a saúde.

Sheet REFERÊNCIAS
A1: REFERÊNCIAS
A2: Link das referências, serve para os dois Municípios
A3: Título | B3: Link
A4: Receita Nominal: | B4: https://siconfi.tesouro.gov.br/siconfi/index.jsf
A5: IPCA (%): | B5: https://sidra.ibge.gov.br/pesquisa/snipc/ipca/tabelas/brasil/dezembro-2020
A6: Receita Real: | B6: https://siconfi.tesouro.gov.br/siconfi/index.jsf
A7: PIB: | B7: https://sidra.ibge.gov.br/pesquisa/pib-munic/tabelas
A8: População: | B8: https://sidra.ibge.gov.br/pesquisa/estimapop/tabelas
A9: Despesas: | B9: https://siconfi.tesouro.gov.br/siconfi/pages/public/consulta_finbra/finbra_list.jsf
A10: Mortalidade Infantil | B10: http://tabnet.datasus.gov.br/cgi/deftohtm.exe?sim/cnv/inf10mg.def
A11: Gasto Saúde | B11: https://siconfi.tesouro.gov.br/siconfi/pages/public/consulta_finbra/finbra_list.jsf
A12: MALÁSIA
A13: PIB | B13: https://data.worldbank.org/indicator/NY.GDP.MKTP.CD?end=2024&locations=MY&start=2014
A14: População | B14: https://data.worldbank.org/indicator/SP.POP.TOTL?locations=MY
A15: PIB Per Capita (US$) | B15: https://data.worldbank.org/indicator/NY.GDP.PCAP.CD?end=2024&locations=MY&start=2014
